Workbook

Sheet Portada
B2: YPF Sociedad Anónima
B3: Estados contables trimestrales — en dólares
B5: Emisor | C5: YPF S.A. (NYSE: YPF), CIK 0000904851
B6: Fuente | C6: SEC EDGAR: estados contables adjuntos a los 6-K y a los 20-F
B7: Moneda y unidad | C7: Dólares estadounidenses, cifras completas. La compañía reporta redondeada al millón, así que en la era dólar los últimos seis dígitos son cero: es el redondeo de la fuente, no una precisión falsa. Los trimestres traducidos desde pesos no terminan en ceros porque el redondeo de origen es al millón de pesos, que son unos pocos miles de dólares.
B8: Split | C8: En 2026 el valor nominal pasó de $10 a $1: por cada acción vieja hay diez nuevas. El ADR de NYSE pasó a representar diez acciones, así que la cantidad de ADR y su precio no cambiaron. La valuación razona en ADR por eso. El resultado por acción de los estados, en cambio, cambia de base con el split.
B9: Norma contable | C9: NIIF (IFRS) tal como las emite el IASB
B10: Cobertura trimestral | C10: 2020Q1 a 2026Q2 (26 trimestres)
B11: Cobertura anual | C11: FY2019 a FY2025
B12: Presentaciones usadas | C12: 39 entre 6-K y 20-F, listadas al pie
B13: Generado | C13: 2026-09-10T19:12:59Z
B15: Cómo se arma cada trimestre
B16: Resultados | C16: El interino publica el trimestre explícito para el 1T, 2T y 3T. El 4T sale del ejercicio menos los nueve meses.
B17: Balance | C17: Es un stock: se toma tal cual a la fecha de cierre de cada trimestre.
B18: Flujo de efectivo | C18: Se publica acumulado. 1T tal cual; 2T = 6M menos 3M; 3T = 9M menos 6M; 4T = ejercicio menos 9M.
B19: Saldos de caja | C19: El saldo al cierre no se resta: es el saldo del acumulado que termina en ese trimestre. La apertura del trimestre es el cierre del anterior.
B20: Resultado por acción | C20: Solo cuando la compañía lo publica para el trimestre. Restar acumulados de un ratio por acción no da el ratio del período.
B21: Traducción de pesos | C21: Saldos al tipo de cambio de cierre; flujos al promedio del período. La resta de acumulados se hace en pesos y se convierte después.
B23: Lo que hay que saber antes de usar un número
B24: El cuarto trimestre no lo publica nadie | C24: YPF no emite un reporte de 4T: emite el ejercicio completo. El 4T de resultados y de flujo de efectivo de este libro sale del ejercicio menos los nueve meses. Es aritmética exacta, no una estimación, pero hereda cualquier reexpresión que la compañía haya hecho entre el 3T y el cierre: si algo se reclasificó, el ajuste cae entero en el 4T.
B25: El flujo de efectivo trimestral es una diferencia | C25: El estado de flujo de efectivo se publica siempre acumulado desde el 1 de enero. Cada trimestre que no sea el primero es la resta de dos acumulados, y esos dos acumulados vienen de dos presentaciones distintas.
B26: El balance empieza en el 4T23 | C26: Los estados en dólares arrancan con el 6-K del 1T24, que trae 2023 como comparativo. Del estado de situación patrimonial, un interino solo muestra dos fechas: el cierre del trimestre y el diciembre anterior. Por eso hay resultados y flujo de todo 2023 pero no balance del 1T, 2T y 3T de ese año: en dólares, esas tres fechas no existen publicadas.
B27: Hasta 2022 los estados venían en pesos, y acá están traducidos | C27: La moneda funcional de YPF es el dólar: los estados en pesos de esos años son esa misma contabilidad traducida según la NIC 21, con tipo de cambio de cierre para los saldos y promedio del período para los flujos. No son pesos reexpresados por inflación —se nota en que los comparativos no cambian de una presentación a la otra—, así que deshacer la traducción es dividir por el mismo tipo de cambio. Esos números van en marrón. El chequeo de que el camino de vuelta funciona está en la hoja Chequeos: el activo de diciembre de 2022 vuelve a dar los 25.912 millones que la compañía publicó en dólares, y el resultado neto de cada trimestre de 2020 a 2022 vuelve con menos de un millón de diferencia contra el que anunció en su earnings release.
B28: El residuo de la traducción está en los ingresos de 2022 | C28: La compañía traduce transacción por transacción y acá se usa el promedio de la cotización diaria del período. Cuando el tipo de cambio se mueve rápido, las dos cosas dejan de ser lo mismo: en 2022, con el peso perdiendo 72%, los ingresos trimestrales quedan entre 4 y 6% por encima de los del release. En 2020 y 2021 la diferencia es menor a 2%.
B29: Restar en pesos, convertir después | C29: El trimestre que sale de restar dos acumulados se arma antes de convertir. Restar dos números ya pasados a dólares con tipos de cambio distintos —el del semestre y el del trimestre— metería esa diferencia adentro del resultado.
B30: Cuando un acumulado tiene dos versiones, se usan las que convivieron | C30: Un acumulado aparece en varias presentaciones y entre 2021 y 2023 la compañía reexpresó algunos comparativos. Restar un ejercicio reexpresado de un acumulado que no lo fue cargaba trece puntos de ingresos en el cuarto trimestre de 2020. Las dos puntas de cada resta se toman de las presentaciones más cercanas entre sí.
B31: Cuando un número cambia, gana el último | C31: Un mismo período aparece en varias presentaciones: primero como período titular y después como comparativo, a veces reexpresado. Este libro toma la versión más reciente. La hoja Datos deja registrada la presentación de la que salió cada número.
B32: EBITDA no es el de la compañía | C32: El EBITDA de la hoja Análisis es resultado operativo más depreciaciones y amortizaciones del estado de flujo. El 'EBITDA ajustado' que YPF publica en su earnings release además excluye partidas que la compañía considera no recurrentes. Los dos números están cruzados en la hoja Chequeos: la diferencia es el ajuste, no un error.
B34: Hojas
B35: Resultados | C35: Estado de resultados integrales, trimestral y anual.
B36: Balance | C36: Estado de situación patrimonial.
B37: Flujo de efectivo | C37: Estado de flujo de efectivo.
B38: Tablero | C38: El trimestre en una pantalla: tarjetas y gráficos sobre fondo oscuro, con botones a cada hoja.
B39: Resumen | C39: Seis números y cinco gráficos: el trimestre y la serie, sin abrir ninguna otra hoja.
B40: Segmentos | C40: Ingresos, resultado operativo, capex y activos por negocio, con el margen de cada uno.
B41: Operativo | C41: Producción, precios de realización y las métricas por barril que salen de cruzarlos con los estados.
B42: Análisis | C42: Márgenes, retornos, estructura de capital, liquidez, capital de trabajo y caja. Todo con fórmulas.
B43: Valuación | C43: Cuatro métodos —descontado, múltiplo, reservas y valor libro— sobre supuestos editables.
B44: Comparables | C44: YPF contra Vista y Pampa: márgenes, apalancamiento y múltiplos, del XBRL de sus 20-F.
B45: Deuda | C45: La escalera de vencimientos y el detalle instrumento por instrumento.
...

Sheet Tablero
AU4: 2T26 | BE4: Consolidado
AG8: Ingresos | BR8: Año anterior
B93: Datos del tablero
B94: Todo lo que muestra el tablero sale de estas celdas. Son fórmulas INDEX contra las hojas de estados, Análisis, Segmentos y Valuación, desplazadas según el trimestre elegido arriba. No hay números escritos a mano.
B96: Listas
N97: Período | T97: Trimestres a elegir | Z97: Métricas | AF97: Segmentos | AL97: Comparación
B98: 1T20 | N98: 2020Q1 | T98: 2T26 | Z98: Ingresos | AF98: Consolidado | AL98: Año anterior
B99: 2T20 | N99: 2020Q2 | T99: 1T26 | Z99: EBITDA ajustado | AF99: Upstream | AL99: Trimestre anterior
B100: 3T20 | N100: 2020Q3 | T100: 4T25 | Z100: Resultado operativo | AF100: Downstream y gas
B101: 4T20 | N101: 2020Q4 | T101: 3T25 | Z101: Capex
B102: 1T21 | N102: 2021Q1 | T102: 2T25 | Z102: Flujo operativo
B103: 2T21 | N103: 2021Q2 | T103: 1T25 | Z103: Flujo de caja libre
B104: 3T21 | N104: 2021Q3 | T104: 4T24 | Z104: Resultado neto
B105: 4T21 | N105: 2021Q4 | T105: 3T24
B106: 1T22 | N106: 2022Q1 | T106: 2T24
B107: 2T22 | N107: 2022Q2 | T107: 1T24
B108: 3T22 | N108: 2022Q3 | T108: 4T23
B109: 4T22 | N109: 2022Q4 | T109: 3T23
B110: 1T23 | N110: 2023Q1 | T110: 2T23
B111: 2T23 | N111: 2023Q2 | T111: 1T23
B112: 3T23 | N112: 2023Q3 | T112: 4T22
B113: 4T23 | N113: 2023Q4
B114: 1T24 | N114: 2024Q1
B115: 2T24 | N115: 2024Q2
B116: 3T24 | N116: 2024Q3
B117: 4T24 | N117: 2024Q4
B118: 1T25 | N118: 2025Q1
B119: 2T25 | N119: 2025Q2
B120: 3T25 | N120: 2025Q3
B121: 4T25 | N121: 2025Q4
B122: 1T26 | N122: 2026Q1
B123: 2T26 | N123: 2026Q2
B125: Selección
N126: Valor
B127: Posición del trimestre elegido | N127: =MATCH($AU$4,$B$98:$B$123,0)
B128: Código | N128: =INDEX($N$98:$N$123,$N$127)
B129: Columna en las hojas de estados | N129: =MATCH($N$128,'Resultados'!$4:$4,0)
B130: Trimestres hacia atrás de la comparación | N130: =IF($BR$8="Trimestre anterior",1,4)
B131: Trimestre de comparación | N131: =INDEX($B$98:$B$123,$N$127-$N$130)
B132: Trimestre del año | N132: =VALUE(RIGHT($N$128,1))
...

Sheet Resumen
B2: YPF de un vistazo
B3: Al cierre de 2026Q2, contra el mismo trimestre del año anterior. Todo referenciado a las hojas de estados.
B5: Ingresos del trimestre | E5: EBITDA del trimestre | H5: Resultado neto
B6: ='Resultados'!AA5 | E6: ='Análisis'!AA13 | H6: ='Resultados'!AA21
B7: =IFERROR('Resultados'!AA5/'Resultados'!W5-1,"") | C7: contra un año antes | E7: =IFERROR('Análisis'!AA13/'Análisis'!W13-1,"") | F7: contra un año antes | H7: =IFERROR('Resultados'!AA21/'Resultados'!W21-1,"") | I7: contra un año antes
B9: Flujo de caja libre | E9: Deuda neta / EBITDA UDM | H9: Margen EBITDA
B10: ='Análisis'!AA15 | E10: ='Análisis'!AA38 | H10: ='Análisis'!AA8
B11: =IFERROR('Análisis'!AA15/'Análisis'!W15-1,"") | C11: contra un año antes
B56: Los gráficos leen las hojas de estados: no hay datos copiados acá. La serie de trimestres arranca en 2020 y los anteriores a 2023 están traducidos desde pesos (ver Portada).

Sheet Resultados
A1: Estado de resultados integrales
A2: Consolidado, en dólares (la compañía reporta redondeado al millón)
A4: En dólares | B4: 2020Q1 | C4: 2020Q2 | D4: 2020Q3 | E4: 2020Q4 | F4: 2021Q1 | G4: 2021Q2 | H4: 2021Q3 | I4: 2021Q4 | J4: 2022Q1 | K4: 2022Q2 | L4: 2022Q3 | M4: 2022Q4 | N4: 2023Q1 | O4: 2023Q2 | P4: 2023Q3 | Q4: 2023Q4 | R4: 2024Q1 | S4: 2024Q2 | T4: 2024Q3 | U4: 2024Q4 | V4: 2025Q1 | W4: 2025Q2 | X4: 2025Q3 | Y4: 2025Q4 | Z4: 2026Q1 | AA4: 2026Q2 | AC4: FY19 | AD4: FY20 | AE4: FY21 | AF4: FY22 | AG4: FY23 | AH4: FY24 | AI4: FY25
A5: Revenues | B5: 2.8440769e+09 | C5: 1.9782046e+09 | D5: 2.3689528e+09 | E5: 2.3436098e+09 | F5: 2.6534915e+09 | G5: 3.3621325e+09 | H5: 3.637745e+09 | I5: 3.6532618e+09 | J5: 3.7655069e+09 | K5: 5.0522633e+09 | L5: 5.4773226e+09 | M5: 4.8542887e+09 | N5: 4238000000 | O5: 4375000000 | P5: 4504000000 | Q5: 4194000000 | R5: 4310000000 | S5: 4935000000 | T5: 5297000000 | U5: 4751000000 | V5: 4608000000 | W5: 4641000000 | X5: 4643000000 | Y5: 4556000000 | Z5: 4946000000 | AA5: 6574000000 | AC5: 1.4097402e+10 | AD5: 9690000000 | AE5: 13682000000 | AF5: 18757000000 | AG5: 17311000000 | AH5: 19293000000 | AI5: 18448000000
A6: Costs | B6: -2.3758552e+09 | C6: -2.1746653e+09 | D6: -2.2169443e+09 | E6: -2.1392176e+09 | F6: -2.2427533e+09 | G6: -2.6497019e+09 | H6: -2.833107e+09 | I6: -3.0395488e+09 | J6: -2.8433938e+09 | K6: -3.481032e+09 | L6: -3.8898364e+09 | M6: -3.9538518e+09 | N6: -3299000000 | O6: -3509000000 | P6: -3689000000 | Q6: -3356000000 | R6: -3019000000 | S6: -3457000000 | T6: -3678000000 | U6: -3756000000 | V6: -3308000000 | W6: -3448000000 | X6: -3319000000 | Y6: -3232000000 | Z6: -3188000000 | AA6: -3609000000 | AC6: -1.1957909e+10 | AD6: -8663000000 | AE6: -10629000000 | AF6: -13684000000 | AG6: -13853000000 | AH6: -13910000000 | AI6: -13348000000
A7: Gross profit | B7: 4.6822164e+08 | C7: -1.9646076e+08 | D7: 1.5200843e+08 | E7: 2.0439221e+08 | F7: 4.107382e+08 | G7: 7.1243068e+08 | H7: 8.0463802e+08 | I7: 6.1371302e+08 | J7: 9.2211308e+08 | K7: 1.5712312e+09 | L7: 1.5874862e+09 | M7: 9.004369e+08 | N7: 939000000 | O7: 866000000 | P7: 815000000 | Q7: 838000000 | R7: 1291000000 | S7: 1478000000 | T7: 1619000000 | U7: 995000000 | V7: 1300000000 | W7: 1193000000 | X7: 1324000000 | Y7: 1324000000 | Z7: 1758000000 | AA7: 2965000000 | AC7: 2.1394929e+09 | AD7: 1027000000 | AE7: 3053000000 | AF7: 5073000000 | AG7: 3458000000 | AH7: 5383000000 | AI7: 5100000000
A8: Selling expenses | B8: -2.2593697e+08 | C8: -3.4315461e+08 | D8: -2.2336991e+08 | E8: -2.304319e+08 | F8: -2.253135e+08 | G8: -2.769659e+08 | H8: -2.8159861e+08 | I8: -2.8502707e+08 | J8: -3.7993584e+08 | K8: -5.3277781e+08 | L8: -5.6240972e+08 | M8: -4.8219902e+08 | N8: -420000000 | O8: -482000000 | P8: -483000000 | Q8: -419000000 | R8: -467000000 | S8: -577000000 | T8: -552000000 | U8: -536000000 | V8: -497000000 | W8: -510000000 | X8: -495000000 | Y8: -530000000 | Z8: -489000000 | AA8: -601000000 | AC8: -1.0366009e+09 | AD8: -1324000000 | AE8: -1507000000 | AF8: -1896000000 | AG8: -1804000000 | AH8: -2132000000 | AI8: -2088000000
A9: Administrative expenses | B9: -1.0989108e+08 | C9: -1.0935387e+08 | D9: -1.2486211e+08 | E9: -1.401868e+08 | F9: -1.0308276e+08 | G9: -1.1614665e+08 | H9: -1.1854942e+08 | I9: -1.4271262e+08 | J9: -1.3857631e+08 | K9: -1.6291826e+08 | L9: -1.7981326e+08 | M9: -2.0885045e+08 | N9: -157000000 | O9: -167000000 | P9: -194000000 | Q9: -187000000 | R9: -141000000 | S9: -210000000 | T9: -224000000 | U9: -261000000 | V9: -258000000 | W9: -233000000 | X9: -207000000 | Y9: -229000000 | Z9: -291000000 | AA9: -323000000 | AC9: -5.131484e+08 | AD9: -467000000 | AE9: -470000000 | AF9: -657000000 | AG9: -705000000 | AH9: -836000000 | AI9: -830000000
A10: Exploration expenses | B10: -11658322 | C10: -2073620.8 | D10: -57597157 | E10: -9650812.5 | F10: -1796181.8 | G10: -8557725.9 | H10: -9908270.8 | I10: -6748912.1 | J10: -10533450 | K10: -13165369 | L10: -19126873 | M10: -23811840 | N10: -18000000 | O10: -8000000 | P10: -16000000 | Q10: -19000000 | R10: -23000000 | S10: -88000000 | T10: -20000000 | U10: -108000000 | V10: -30000000 | W10: -21000000 | X10: -17000000 | Y10: -48000000 | Z10: -20000000 | AA10: -17000000 | AC10: -1.4211765e+08 | AD10: -80000000 | AE10: -30000000 | AF10: -65000000 | AG10: -61000000 | AH10: -239000000 | AI10: -116000000
A11: Inventories write-down and reversal of impairment losses of property, plant and equipment | C11: -8.5061405e+08 | L11: -1.0406553e+08 | M11: -26657164 | P11: -506000000 | Q11: -1782000000 | S11: -5000000 | T11: -21000000 | U11: -61000000 | W11: 9000000 | X11: -5000000 | Y11: 0 | AA11: -8000000 | AF11: -123000000 | AG11: -2288000000 | AH11: -87000000 | AI11: 4000000
A12: Other net operating results | B12: 1.2021423e+08 | C12: 1.1760392e+08 | D12: -47738184 | E12: -98483291 | F12: -3117900.5 | G12: -585416.57 | H12: 33809531 | I12: -2.608783e+08 | J12: -13666284 | K12: -11614009 | L12: -18278593 | M12: 2.2004041e+08 | N12: -9000000 | O12: 12000000 | P12: -3000000 | Q12: 152000000 | R12: 6000000 | S12: -8000000 | T12: -48000000 | U12: -559000000 | V12: -323000000 | W12: -26000000 | X12: -48000000 | Y12: 67000000 | Z12: -80000000 | AA12: -203000000 | AC12: -23475069 | AD12: 93000000 | AE12: -232000000 | AF12: 150000000 | AG12: 152000000 | AH12: -609000000 | AI12: -330000000
A13: Operating profit | B13: 2.409495e+08 | C13: -1.384053e+09 | D13: -3.2074434e+08 | E13: 5.4677103e+08 | F13: 77427862 | G13: 3.1017499e+08 | H13: 4.2839124e+08 | I13: -1.9371767e+08 | J13: 3.7940119e+08 | K13: 8.507558e+08 | L13: 7.037922e+08 | M13: 3.7895883e+08 | N13: 335000000 | O13: 221000000 | P13: -387000000 | Q13: -1417000000 | R13: 666000000 | S13: 590000000 | T13: 754000000 | U13: -530000000 | V13: 192000000 | W13: 412000000 | X13: 552000000 | Y13: 584000000 | Z13: 878000000 | AA13: 1813000000 | AC13: -4.3651164e+08 | AD13: -804000000 | AE13: 699000000 | AF13: 2482000000 | AG13: -1248000000 | AH13: 1480000000 | AI13: 1740000000
A14: Income from equity interests in associates and joint ventures | B14: 23121252 | C14: 34066627 | D14: 61857544 | E14: 62755283 | F14: 57794126 | G14: 15316626 | H14: 44839298 | I14: 1.5990343e+08 | J14: 1.1470487e+08 | K14: 1.3110266e+08 | L14: 1.4043093e+08 | M14: 70052977 | N14: 89000000 | O14: 94000000 | P14: 44000000 | Q14: -133000000 | R14: 129000000 | S14: 27000000 | T14: 107000000 | U14: 133000000 | V14: 81000000 | W14: -6000000 | X14: 32000000 | Y14: 15000000 | Z14: 101000000 | AA14: 115000000 | AC14: 1.655304e+08 | AD14: 188000000 | AE14: 287000000 | AF14: 446000000 | AG14: 94000000 | AH14: 396000000 | AI14: 122000000
A15: Financial income | B15: 3.3877519e+08 | C15: 4.5644837e+08 | D15: 3.0383934e+08 | E15: 4.21648e+08 | F15: 2.5244827e+08 | G15: 2.0557701e+08 | H15: 1.5818251e+08 | I15: 3.0052567e+08 | J15: 3.0118352e+08 | K15: 4.5554041e+08 | L15: 6.4385199e+08 | M15: 8.3124801e+08 | N15: 45000000 | O15: 81000000 | P15: 104000000 | Q15: 104000000 | R15: 36000000 | S15: 32000000 | T15: 19000000 | U15: 47000000 | V15: 16000000 | W15: 28000000 | X15: 28000000 | Y15: 33000000 | Z15: 32000000 | AA15: 63000000 | AC15: 1.9404326e+09 | AD15: 1492000000 | AE15: 904000000 | AF15: 320000000 | AG15: 334000000 | AH15: 134000000 | AI15: 105000000
A16: Financial costs | J16: -4.0367597e+08 | K16: -5.1678099e+08 | L16: -6.3455779e+08 | M16: -7.9393168e+08 | N16: -279000000 | O16: -295000000 | P16: -319000000 | Q16: -256000000 | R16: -336000000 | S16: -308000000 | T16: -267000000 | U16: -258000000 | V16: -285000000 | W16: -279000000 | X16: -257000000 | Y16: -266000000 | Z16: -304000000 | AA16: -312000000 | AD16: -1966000000 | AE16: -1408000000 | AF16: -988000000 | AG16: -1149000000 | AH16: -1169000000 | AI16: -1087000000
A17: Other financial results | B17: -21053366 | C17: 1.7884979e+08 | D17: 50318995 | E17: 67280664 | F17: 64221972 | G17: 56008400 | H17: 67238369 | I17: 65478384 | J17: 59392528 | K17: 59485765 | L17: 1.1417113e+08 | M17: 1.5736306e+08 | N17: 236000000 | O17: 354000000 | P17: 421000000 | Q17: 701000000 | R17: 41000000 | S17: 115000000 | T17: 38000000 | U17: 108000000 | V17: 24000000 | W17: -5000000 | X17: -16000000 | Y17: 27000000 | Z17: -55000000 | AA17: 119000000 | AC17: 86463043 | AD17: 253000000 | AE17: 233000000 | AF17: 796000000 | AG17: 311000000 | AH17: 179000000 | AI17: 30000000
A18: Net financial results | B18: -1.729372e+08 | C18: 77197939 | D18: -1.017304e+08 | E18: 19476640 | F18: -48474315 | G18: -1.1572089e+08 | H18: -81828118 | I18: 15628012 | J18: -43099915 | K18: -1754817.4 | L18: 1.2346533e+08 | M18: 1.9467938e+08 | N18: 2000000 | O18: 140000000 | P18: 206000000 | Q18: 549000000 | R18: -259000000 | S18: -161000000 | T18: -210000000 | U18: -103000000 | V18: -245000000 | W18: -256000000 | X18: -245000000 | Y18: -206000000 | Z18: -327000000 | AA18: -130000000 | AC18: 1.2535272e+08 | AD18: -221000000 | AE18: -271000000 | AF18: 128000000 | AG18: -504000000 | AH18: -856000000 | AI18: -952000000
A19: Net profit before income tax | B19: 91133556 | C19: -1.2727884e+09 | D19: -3.6061719e+08 | E19: 6.2900295e+08 | F19: 86747673 | G19: 2.0977072e+08 | H19: 3.9140242e+08 | I19: -18186228 | J19: 4.5100614e+08 | K19: 9.8010364e+08 | L19: 9.6768846e+08 | M19: 6.4369119e+08 | N19: 426000000 | O19: 455000000 | P19: -137000000 | Q19: -1001000000 | R19: 536000000 | S19: 456000000 | T19: 651000000 | U19: -500000000 | V19: 28000000 | W19: 150000000 | X19: 339000000 | Y19: 393000000 | Z19: 652000000 | AA19: 1798000000 | AC19: -1.4562853e+08 | AD19: -837000000 | AE19: 715000000 | AF19: 3056000000 | AG19: -1658000000 | AH19: 1020000000 | AI19: 910000000
A20: Income tax | B20: 12277059 | C20: 13093434 | D20: -1.2184434e+08 | E20: -91307687 | F20: -1.1213145e+08 | G20: -7.0218057e+08 | H20: -1.5505466e+08 | I20: 2.643523e+08 | J20: -2.0322149e+08 | K20: -1.8269598e+08 | L20: -2.8772186e+08 | M20: -1.6472634e+08 | N20: -85000000 | O20: -75000000 | P20: 0 | Q20: -860000000 | R20: 121000000 | S20: 79000000 | T20: 834000000 | U20: 216000000 | V20: -38000000 | W20: -92000000 | X20: -537000000 | Y20: -1042000000 | Z20: -243000000 | AA20: -593000000 | AC20: -5.4780009e+08 | AD20: -184000000 | AE20: -699000000 | AF20: -822000000 | AG20: 381000000 | AH20: 1373000000 | AI20: -1709000000
A21: Net profit for the period | B21: 1.0341061e+08 | D21: -4.8246153e+08 | E21: 5.3769527e+08 | F21: -25383777 | G21: -4.9240985e+08 | H21: 2.3634776e+08 | I21: 2.4616607e+08 | J21: 2.4778465e+08 | K21: 7.9740766e+08 | L21: 6.7996659e+08 | M21: 4.7896486e+08 | N21: 341000000 | O21: 380000000 | P21: -137000000 | Q21: -1861000000 | R21: 657000000 | S21: 535000000 | T21: 1485000000 | U21: -284000000 | V21: -10000000 | W21: 58000000 | X21: -198000000 | Y21: -649000000 | Z21: 409000000 | AA21: 1205000000 | AC21: -6.9342862e+08 | AD21: -1021000000 | AE21: 16000000 | AF21: 2234000000 | AG21: -1277000000 | AH21: 2393000000 | AI21: -799000000
A22: Translation effect from subsidiaries, associates and joint ventures | J22: -35971311 | K22: -58324364 | L22: -78779406 | M22: -82588448 | N22: -85000000 | O22: -106000000 | P22: -97000000 | Q22: -154000000 | R22: -27000000 | S22: -29000000 | T22: -22000000 | U22: -25000000 | V22: -38000000 | W22: -84000000 | X22: -99000000 | Y22: -37000000 | Z22: 51000000 | AA22: -67000000 | AD22: -111000000 | AE22: -62000000 | AF22: -194000000 | AG22: -442000000 | AH22: -103000000 | AI22: -258000000
A23: Result from net monetary position in subsidiaries, associates and joint ventures (1) | B23: 35723963 | C23: 23224553 | D23: 33864616 | E23: 48904117 | F23: 53128572 | G23: 53805105 | H23: 48296390 | I23: 50497391 | J23: 78583480 | K23: 91759145 | L23: 1.295877e+08 | M23: 1.1012822e+08 | N23: 101000000 | O23: 100000000 | P23: 73000000 | Q23: -53000000 | R23: 285000000 | S23: 131000000 | T23: 69000000 | U23: 42000000 | V23: 84000000 | W23: 39000000 | X23: 12000000 | Y23: 55000000 | Z23: 128000000 | AA23: 45000000 | AC23: 1.8599318e+08 | AD23: 96000000 | AE23: 177000000 | AF23: 276000000 | AG23: 221000000 | AH23: 527000000 | AI23: 190000000
A24: Other comprehensive income for the period | B24: 7.0461202e+08 | C24: 8.2565654e+08 | D24: 6.3057826e+08 | E24: 7.6635202e+08 | F24: 7.4172141e+08 | G24: 3.71516e+08 | H24: 2.755487e+08 | I24: 3.7894445e+08 | J24: 7.1238204e+08 | K24: 1.1166742e+09 | L24: 1.6380805e+09 | M24: 1.8786233e+09 | N24: 16000000 | O24: -6000000 | P24: -24000000 | Q24: -207000000 | R24: 258000000 | S24: 102000000 | T24: 47000000 | U24: 17000000 | V24: 46000000 | W24: -45000000 | X24: -87000000 | Y24: 64000000 | Z24: 179000000 | AA24: -22000000 | AC24: 4.5987661e+09 | AD24: -15000000 | AE24: 115000000 | AF24: 82000000 | AG24: -221000000 | AH24: 424000000 | AI24: -22000000
A25: Total comprehensive income for the period | B25: 8.0802264e+08 | C25: -4.3403845e+08 | D25: 1.4811673e+08 | E25: 1.3040473e+09 | F25: 7.1633763e+08 | G25: -1.2089384e+08 | H25: 5.1189646e+08 | I25: 6.2511052e+08 | J25: 9.6016669e+08 | K25: 1.9140819e+09 | L25: 2.3180471e+09 | M25: 2.3575882e+09 | N25: 357000000 | O25: 374000000 | P25: -161000000 | Q25: -2068000000 | R25: 915000000 | S25: 637000000 | T25: 1532000000 | U25: -267000000 | V25: 36000000 | W25: 13000000 | X25: -285000000 | Y25: -585000000 | Z25: 588000000 | AA25: 1183000000 | AC25: 3.9053375e+09 | AD25: -1036000000 | AE25: 131000000 | AF25: 2316000000 | AG25: -1498000000 | AH25: 2817000000 | AI25: -821000000
A26: Shareholders of the parent company (del resultado) | B26: 1.0114734e+08 | C26: -1.2535038e+09 | D26: -4.8429131e+08 | E26: 5.5298405e+08 | F26: -23339067 | G26: -4.7915814e+08 | H26: 2.3150165e+08 | I26: 2.4726103e+08 | J26: 2.4952928e+08 | K26: 7.8913373e+08 | L26: 6.7785696e+08 | M26: 4.7815632e+08 | N26: 341000000 | O26: 335000000 | P26: -128000000 | Q26: -1860000000 | R26: 649000000 | S26: 519000000 | T26: 1470000000 | U26: -290000000 | V26: -16000000 | W26: 50000000 | X26: -206000000 | Y26: -654000000 | Z26: 404000000 | AA26: 1201000000 | AC26: -7.078045e+08 | AD26: -1004000000 | AE26: 26000000 | AF26: 2228000000 | AG26: -1312000000 | AH26: 2348000000 | AI26: -826000000
A27: Non-controlling interest (del resultado) | B27: 2263277.5 | C27: -6191239.2 | D27: 1829781.6 | E27: -15288787 | F27: -2044710.1 | G27: -13251702 | H27: 4846101.3 | I27: -1094956.2 | J27: -1744632.1 | K27: 8273921.4 | L27: 2109635.8 | M27: 808540.97 | N27: 177025.01 | O27: 45000000 | P27: -9000000 | Q27: -1000000 | R27: 8000000 | S27: 16000000 | T27: 15000000 | U27: 6000000 | V27: 6000000 | W27: 8000000 | X27: 8000000 | Y27: 5000000 | Z27: 5000000 | AA27: 4000000 | AC27: 14375883 | AD27: -17000000 | AE27: -10000000 | AF27: 6000000 | AG27: 35000000 | AH27: 45000000 | AI27: 27000000
A28: Shareholders of the parent company (de otro resultado integral) | B28: 6.9767565e+08 | C28: 8.209909e+08 | D28: 6.2383265e+08 | E28: 7.5700123e+08 | F28: 7.3281958e+08 | G28: 3.6324566e+08 | H28: 2.683773e+08 | I28: 3.7034407e+08 | J28: 7.0015086e+08 | K28: 1.1023644e+09 | L28: 1.6195438e+09 | M28: 1.8642054e+09 | N28: 14000000 | O28: -7000000 | P28: -24000000 | Q28: -173000000 | R28: 214000000 | S28: 85000000 | T28: 40000000 | U28: 14000000 | V28: 37000000 | W28: -34000000 | X28: -71000000 | Y28: 61000000 | Z28: 145000000 | AA28: -18000000 | AC28: 4.5634288e+09 | AD28: -13000000 | AE28: 98000000 | AF28: 70000000 | AG28: -190000000 | AH28: 353000000 | AI28: -7000000
A29: Non-controlling interest (de otro resultado integral) | B29: 6936375.7 | C29: 4665646.7 | D29: 6745612.9 | E29: 9350787.2 | F29: 8901831.8 | G29: 8270339.6 | H29: 7171406.8 | I29: 8600383.6 | J29: 12231184 | K29: 14309815 | L29: 18536765 | M29: 14417952 | N29: 2000000 | O29: 1000000 | P29: 0 | Q29: -34000000 | R29: 44000000 | S29: 17000000 | T29: 7000000 | U29: 3000000 | V29: 9000000 | W29: -11000000 | X29: -16000000 | Y29: 3000000 | Z29: 34000000 | AA29: -4000000 | AC29: 35337250 | AD29: -2000000 | AE29: 17000000 | AF29: 12000000 | AG29: -31000000 | AH29: 71000000 | AI29: -15000000
A30: Shareholders of the parent company (del resultado integral) | B30: 7.9882298e+08 | C30: -4.3251286e+08 | D30: 1.3954133e+08 | E30: 1.3099853e+09 | F30: 7.0948051e+08 | G30: -1.1591248e+08 | H30: 4.9987895e+08 | I30: 6.1760509e+08 | J30: 9.4968014e+08 | K30: 1.8914981e+09 | L30: 2.2974007e+09 | M30: 2.3423617e+09 | N30: 355000000 | O30: 328000000 | P30: -152000000 | Q30: -2033000000 | R30: 863000000 | S30: 604000000 | T30: 1510000000 | U30: -276000000 | V30: 21000000 | W30: 16000000 | X30: -277000000 | Y30: -593000000 | Z30: 549000000 | AA30: 1183000000 | AC30: 3.8556243e+09 | AD30: -1017000000 | AE30: 124000000 | AF30: 2298000000 | AG30: -1502000000 | AH30: 2701000000 | AI30: -833000000
A31: Non-controlling interest (del resultado integral) | B31: 9199653.2 | C31: -1525592.4 | D31: 8575394.6 | E31: -5937999.9 | F31: 6857121.7 | G31: -4981362.8 | H31: 12017508 | I31: 7505427.4 | J31: 10486552 | K31: 22583736 | L31: 20646401 | M31: 15226493 | N31: 2000000 | O31: 46000000 | P31: -9000000 | Q31: -35000000 | R31: 52000000 | S31: 33000000 | T31: 22000000 | U31: 9000000 | V31: 15000000 | W31: -3000000 | X31: -8000000 | Y31: 8000000 | Z31: 39000000 | AA31: 0 | AC31: 49713134 | AD31: -19000000 | AE31: 7000000 | AF31: 18000000 | AG31: 4000000 | AH31: 116000000 | AI31: 12000000
A32: Basic and diluted (2) | B32: 257753.12 | C32: -3194412.8 | D32: -1232917.8 | F32: -59420.857 | G32: -1220540.3 | H32: 589866.22 | J32: 634914.75 | K32: 2007782.3 | L32: 1724000.3 | N32: 870000 | O32: 860000 | P32: -330000 | R32: 1660000 | S32: 1320000 | T32: 3750000 | V32: -40000 | W32: 10000 | X32: -530000 | Z32: 1030000 | AA32: 310000 | AC32: -1804256.4 | AD32: -2560000 | AE32: 70000 | AF32: 5670000 | AG32: -3350000 | AH32: 5990000 | AI32: -2110000
A34: Líneas de presentaciones anteriores
A35: (Impairment) / Recovery of property, plant and equipment | AC35: -8.6066252e+08
A36: Recovery / (Impairment) of property, plant and equipment and intangible assets, net | AC36: -8.6066252e+08 | AD36: 97140482
A37: Impairment of property, plant and equipment and intangible assets | D37: -19185397 | AE37: -115000000 | AF37: -123000000 | AG37: -2288000000
A38: (Impairment) / Recovery of property, plant and equipment and intangible assets, net | AC38: -8.6066252e+08 | AD38: -53000000 | AE38: -115000000 | AF38: -123000000
A39: Financial loss | B39: -4.9065903e+08 | C39: -5.5810022e+08 | D39: -4.5588873e+08 | E39: -4.6945202e+08 | F39: -3.6514455e+08 | G39: -3.773063e+08 | H39: -3.07249e+08 | I39: -3.5037605e+08 | J39: -4.0367597e+08 | K39: -5.1678099e+08 | L39: -6.3455779e+08 | AC39: -1.9015429e+09 | AD39: -1.9673819e+09 | AE39: -1.3975448e+09
A40: Net loss for the year | C40: -1.259695e+09 | D40: -4.8246153e+08 | E40: 5.3769527e+08 | G40: -4.9240985e+08 | AC40: -6.9342862e+08 | AD40: -1.0069516e+09 | AE40: -8501085.8
A41: Translation differences from subsidiaries, associates and joint ventures | B41: -29520303 | C41: -33725961 | D41: -29890985 | E41: -34027865 | F41: -35754185 | G41: -14326740 | H41: -12871492 | I41: -17718383 | J41: -35971311 | K41: -58324364 | L41: -78779406 | AC41: -1.664237e+08 | AD41: -1.2762538e+08 | AE41: -79350481
A42: Translation differences from YPF (2) | B42: 6.9840836e+08 | C42: 8.3615795e+08 | D42: 6.2660463e+08 | E42: 7.5147576e+08 | F42: 7.2434702e+08 | G42: 3.3203764e+08 | H42: 2.401238e+08 | I42: 3.4616544e+08 | J42: 6.6976987e+08 | K42: 1.0832394e+09 | L42: 1.5872723e+09 | M42: 1.8510836e+09 | N42: 1.7937579e+09 | O42: 2.2692086e+09 | P42: 3.3811473e+09 | Q42: 1.1810036e+10 | AC42: 4.5791966e+09 | AD42: 2.9116197e+09 | AE42: 1.6142489e+09 | AF42: 5.470608e+09 | AG42: 2.4153373e+10 | AH42: 2.5635005e+09
...

Sheet Balance
A1: Estado de situación patrimonial
A2: Consolidado, en dólares (la compañía reporta redondeado al millón)
A4: En dólares | B4: 2020Q1 | C4: 2020Q2 | D4: 2020Q3 | E4: 2020Q4 | F4: 2021Q1 | G4: 2021Q2 | H4: 2021Q3 | I4: 2021Q4 | J4: 2022Q1 | K4: 2022Q2 | L4: 2022Q3 | M4: 2022Q4 | N4: 2023Q1 | O4: 2023Q2 | P4: 2023Q3 | Q4: 2023Q4 | R4: 2024Q1 | S4: 2024Q2 | T4: 2024Q3 | U4: 2024Q4 | V4: 2025Q1 | W4: 2025Q2 | X4: 2025Q3 | Y4: 2025Q4 | Z4: 2026Q1 | AA4: 2026Q2 | AC4: FY19 | AD4: FY20 | AE4: FY21 | AF4: FY22 | AG4: FY23 | AH4: FY24 | AI4: FY25
A5: Intangible assets (no corriente) | E5: 465000000 | I5: 419000000 | J5: 4.1606046e+08 | K5: 4.1382772e+08 | L5: 4.1216981e+08 | M5: 384000000 | N5: 3.796527e+08 | O5: 3.7567428e+08 | P5: 3.7075011e+08 | Q5: 367000000 | R5: 377000000 | S5: 389000000 | T5: 407000000 | U5: 491000000 | V5: 594000000 | W5: 590000000 | X5: 1056000000 | Y5: 1068000000 | Z5: 1073000000 | AA5: 1079000000 | AC5: 6.2083371e+08 | AD5: 465000000 | AE5: 419000000 | AF5: 384000000 | AG5: 367000000 | AH5: 491000000 | AI5: 1068000000
A6: Property, plant and equipment (no corriente) | E6: 16413000000 | I6: 16003000000 | J6: 1.6101993e+10 | K6: 1.6312308e+10 | L6: 1.6643162e+10 | M6: 17510000000 | N6: 1.8061816e+10 | O6: 1.8581044e+10 | P6: 1.8640831e+10 | Q6: 17712000000 | R6: 16699000000 | S6: 17423000000 | T6: 18102000000 | U6: 18736000000 | V6: 18957000000 | W6: 19348000000 | X6: 19627000000 | Y6: 19085000000 | Z6: 19558000000 | AA6: 20433000000 | AC6: 1.7850885e+10 | AD6: 16413000000 | AE6: 16003000000 | AF6: 17510000000 | AG6: 17712000000 | AH6: 18736000000 | AI6: 19085000000
A7: Right-of-use assets (no corriente) | E7: 524000000 | I7: 519000000 | J7: 4.953697e+08 | K7: 5.2042334e+08 | L7: 5.0004796e+08 | M7: 541000000 | N7: 5.3983831e+08 | O7: 5.0854327e+08 | P7: 5.0333248e+08 | Q7: 631000000 | R7: 614000000 | S7: 565000000 | T7: 551000000 | U7: 743000000 | V7: 656000000 | W7: 672000000 | X7: 588000000 | Y7: 537000000 | Z7: 609000000 | AA7: 689000000 | AC7: 1.0251379e+09 | AD7: 524000000 | AE7: 519000000 | AF7: 541000000 | AG7: 631000000 | AH7: 743000000 | AI7: 537000000
A8: Investments in associates and joint ventures (no corriente) | E8: 1274000000 | I8: 1529000000 | J8: 1.6495386e+09 | K8: 1.714347e+09 | L8: 1.8678068e+09 | M8: 1905000000 | N8: 1.8054192e+09 | O8: 1.8093587e+09 | P8: 1.8355412e+09 | Q8: 1676000000 | R8: 1834000000 | S8: 1745000000 | T8: 1858000000 | U8: 1960000000 | V8: 2104000000 | W8: 1913000000 | X8: 1917000000 | Y8: 1610000000 | Z8: 1717000000 | AA8: 2056000000 | AC8: 1.1286519e+09 | AD8: 1274000000 | AE8: 1529000000 | AF8: 1905000000 | AG8: 1676000000 | AH8: 1960000000 | AI8: 1610000000
A9: Deferred income tax assets, net (no corriente) | E9: 33000000 | I9: 19000000 | J9: 14640182 | K9: 14455538 | L9: 6194923.5 | M9: 17000000 | N9: 16019041 | O9: 16019693 | P9: 16972394 | Q9: 18000000 | R9: 18000000 | S9: 19000000 | T9: 67000000 | U9: 330000000 | V9: 309000000 | W9: 231000000 | X9: 4000000 | Y9: 9000000 | Z9: 41000000 | AA9: 24000000 | AC9: 26433733 | AD9: 33000000 | AE9: 19000000 | AF9: 17000000 | AG9: 18000000 | AH9: 330000000 | AI9: 9000000
A10: Other receivables (no corriente) | E10: 175000000 | I10: 190000000 | J10: 54011010 | K10: 50147141 | L10: 45186900 | M10: 205000000 | N10: 2.0713996e+08 | O10: 2.1218676e+08 | P10: 2.0256314e+08 | Q10: 158000000 | R10: 177000000 | S10: 242000000 | T10: 290000000 | U10: 337000000 | V10: 438000000 | W10: 760000000 | X10: 774000000 | Y10: 648000000 | Z10: 636000000 | AA10: 797000000 | AC10: 1.9685867e+08 | AD10: 175000000 | AE10: 190000000 | AF10: 205000000 | AG10: 158000000 | AH10: 337000000 | AI10: 648000000
A11: Trade receivables (no corriente) | E11: 101000000 | I11: 43000000 | J11: 42397967 | K11: 40283832 | L11: 10050600 | M11: 6000000 | N11: 5278947.5 | O11: 4867582 | P11: 3245352.6 | Q11: 31000000 | R11: 31000000 | S11: 32000000 | T11: 31000000 | U11: 1000000 | V11: 2000000 | W11: 2000000 | X11: 1000000 | Y11: 5000000 | Z11: 6000000 | AA11: 6000000 | AC11: 2.5590459e+08 | AD11: 101000000 | AE11: 43000000 | AF11: 6000000 | AG11: 31000000 | AH11: 1000000 | AI11: 5000000
A12: Total non-current assets | E12: 18985000000 | I12: 18747000000 | J12: 1.8808832e+10 | K12: 1.9244602e+10 | L12: 1.9686012e+10 | M12: 20769000000 | N12: 2.118305e+10 | O12: 2.157262e+10 | P12: 2.1583963e+10 | Q12: 20601000000 | R12: 19757000000 | S12: 20422000000 | T12: 21306000000 | U12: 22598000000 | V12: 23060000000 | W12: 23516000000 | X12: 23967000000 | Y12: 22962000000 | Z12: 23640000000 | AA12: 25084000000 | AC12: 2.1104706e+10 | AD12: 18985000000 | AE12: 18747000000 | AF12: 20769000000 | AG12: 20601000000 | AH12: 22598000000 | AI12: 22962000000
A13: Assets held for sale | B13: 28346364 | E13: 6000000 | F13: 5870662.6 | H13: 1002632.2 | I13: 1000000 | J13: 1000037 | K13: 998310.66 | R13: 1858000000 | S13: 1940000000 | T13: 2072000000 | U13: 1537000000 | V13: 1534000000 | W13: 529000000 | X13: 489000000 | Y13: 1019000000 | Z13: 957000000 | AA13: 432000000 | AD13: 6000000 | AE13: 1000000 | AH13: 1537000000 | AI13: 1019000000
A14: Inventories | B14: 1.5213274e+09 | C14: 1.4388405e+09 | D14: 1.3689253e+09 | E14: 1191000000 | F14: 1.2104763e+09 | G14: 1.2977446e+09 | H14: 1.3975984e+09 | I14: 1500000000 | J14: 1.5090649e+09 | K14: 1.7217025e+09 | L14: 2.0027419e+09 | M14: 1738000000 | N14: 1.8669974e+09 | O14: 1.8944731e+09 | P14: 1.761338e+09 | Q14: 1683000000 | R14: 1574000000 | S14: 1577000000 | T14: 1713000000 | U14: 1546000000 | V14: 1617000000 | W14: 1482000000 | X14: 1529000000 | Y14: 1447000000 | Z14: 1460000000 | AA14: 1643000000 | AC14: 1.343879e+09 | AD14: 1191000000 | AE14: 1500000000 | AF14: 1738000000 | AG14: 1683000000 | AH14: 1546000000 | AI14: 1447000000
A15: Contract assets | B15: 11226591 | C15: 6279052 | D15: 5592701.7 | E15: 10000000 | F15: 4283409.4 | G15: 14639164 | H15: 10826402 | I15: 13000000 | J15: 15901490 | K15: 17314700 | L15: 1251224.9 | M15: 1000000 | N15: 8985238.6 | O15: 6335273.1 | P15: 7799130.9 | Q15: 10000000 | R15: 17000000 | S15: 21000000 | T15: 38000000 | U15: 30000000 | V15: 25000000 | W15: 21000000 | X15: 7000000 | Y15: 3000000 | Z15: 5000000 | AA15: 7000000 | AC15: 3389796.5 | AD15: 10000000 | AE15: 13000000 | AF15: 1000000 | AG15: 10000000 | AH15: 30000000 | AI15: 3000000
A16: Other receivables (corriente) | B16: 6.00436e+08 | C16: 4.6230586e+08 | D16: 3.8951985e+08 | E16: 409000000 | F16: 5.1552027e+08 | G16: 4.6243458e+08 | H16: 4.6194e+08 | I16: 616000000 | J16: 5.0628002e+08 | K16: 6.0316333e+08 | L16: 6.1433784e+08 | M16: 808000000 | N16: 6.4483231e+08 | O16: 7.3095312e+08 | P16: 4.8342327e+08 | Q16: 381000000 | R16: 444000000 | S16: 482000000 | T16: 498000000 | U16: 552000000 | V16: 634000000 | W16: 661000000 | X16: 671000000 | Y16: 1159000000 | Z16: 820000000 | AA16: 666000000 | AC16: 6.0435229e+08 | AD16: 409000000 | AE16: 616000000 | AF16: 808000000 | AG16: 381000000 | AH16: 552000000 | AI16: 1159000000
A17: Trade receivables (corriente) | B17: 1.7133923e+09 | C17: 1.4344935e+09 | D17: 1.461415e+09 | E17: 1287000000 | F17: 1.2914914e+09 | G17: 1.468096e+09 | H17: 1.6135492e+09 | I17: 1305000000 | J17: 1.3931147e+09 | K17: 1.5457283e+09 | L17: 1.6752066e+09 | M17: 1504000000 | N17: 1.3210219e+09 | O17: 1.3623257e+09 | P17: 1.4901654e+09 | Q17: 973000000 | R17: 1400000000 | S17: 1703000000 | T17: 1936000000 | U17: 1620000000 | V17: 1614000000 | W17: 1795000000 | X17: 1890000000 | Y17: 1654000000 | Z17: 1784000000 | AA17: 2087000000 | AC17: 1.9717094e+09 | AD17: 1287000000 | AE17: 1305000000 | AF17: 1504000000 | AG17: 973000000 | AH17: 1620000000 | AI17: 1654000000
A18: Investments in financial assets (corriente) | B18: 84836950 | C18: 1.1533851e+08 | D18: 2.2009775e+08 | E18: 344000000 | F18: 3.818866e+08 | G18: 3.9424387e+08 | H18: 4.0982338e+08 | I18: 497000000 | J18: 5.3319092e+08 | K18: 5.7508284e+08 | L18: 5.0100678e+08 | M18: 319000000 | N18: 2.8230143e+08 | O18: 3.0320703e+08 | P18: 1.8129694e+08 | Q18: 264000000 | R18: 290000000 | S18: 353000000 | T18: 318000000 | U18: 390000000 | V18: 292000000 | W18: 237000000 | X18: 217000000 | Y18: 262000000 | Z18: 366000000 | AA18: 1156000000 | AC18: 1.3976649e+08 | AD18: 344000000 | AE18: 497000000 | AF18: 319000000 | AG18: 264000000 | AH18: 390000000 | AI18: 262000000
A19: Cash and cash equivalents | B19: 1.0749538e+09 | C19: 1.1867834e+09 | D19: 7.8299136e+08 | E19: 650000000 | F19: 6.1181001e+08 | G19: 5.3989362e+08 | H19: 6.2282702e+08 | I19: 611000000 | J19: 7.9471413e+08 | K19: 6.6687951e+08 | L19: 8.3500904e+08 | M19: 773000000 | N19: 1.0160176e+09 | O19: 1.1678606e+09 | P19: 1.2934416e+09 | Q19: 1123000000 | R19: 1309000000 | S19: 1041000000 | T19: 877000000 | U19: 1118000000 | V19: 938000000 | W19: 774000000 | X19: 799000000 | Y19: 933000000 | Z19: 1326000000 | AA19: 1318000000 | AC19: 1.1037712e+09 | AD19: 650000000 | AE19: 611000000 | AF19: 773000000 | AG19: 1123000000 | AH19: 1118000000 | AI19: 933000000
A20: Total current assets | B20: 5.0345195e+09 | C20: 4.6440408e+09 | D20: 4.2285419e+09 | E20: 3897000000 | F20: 4.0213386e+09 | G20: 4.1770519e+09 | H20: 4.517567e+09 | I20: 4543000000 | J20: 4.7532662e+09 | K20: 5.1308695e+09 | L20: 5.6295534e+09 | M20: 5143000000 | N20: 5.1401558e+09 | O20: 5.4651548e+09 | P20: 5.2174643e+09 | Q20: 4434000000 | R20: 6892000000 | S20: 7117000000 | T20: 7452000000 | U20: 6793000000 | V20: 6654000000 | W20: 5499000000 | X20: 5602000000 | Y20: 6477000000 | Z20: 6718000000 | AA20: 7309000000 | AC20: 5.1668681e+09 | AD20: 3897000000 | AE20: 4543000000 | AF20: 5143000000 | AG20: 4434000000 | AH20: 6793000000 | AI20: 6477000000
A21: TOTAL ASSETS | B21: 2.582702e+10 | C21: 2.3824755e+10 | D21: 2.2878692e+10 | E21: 22882000000 | F21: 2.2670662e+10 | G21: 2.2598282e+10 | H21: 2.3023585e+10 | I21: 23290000000 | J21: 2.3562098e+10 | K21: 2.4375472e+10 | L21: 2.5315565e+10 | M21: 25912000000 | N21: 2.6323206e+10 | O21: 2.7037775e+10 | P21: 2.6801428e+10 | Q21: 25035000000 | R21: 26649000000 | S21: 27539000000 | T21: 28758000000 | U21: 29391000000 | V21: 29714000000 | W21: 29015000000 | X21: 29569000000 | Y21: 29439000000 | Z21: 30358000000 | AA21: 32393000000 | AC21: 2.6271574e+10 | AD21: 22882000000 | AE21: 23290000000 | AF21: 25912000000 | AG21: 25035000000 | AH21: 29391000000 | AI21: 29439000000
A22: Capital | Q22: 3919000000 | U22: 3922000000 | Y22: 3921000000 | Z22: 3921000000 | AA22: 3916000000 | AG22: 3919000000 | AH22: 3922000000 | AI22: 3921000000
A23: Treasury shares | Q23: 14000000 | U23: 11000000 | Y23: 12000000 | Z23: 12000000 | AA23: 17000000 | AG23: 14000000 | AH23: 11000000 | AI23: 12000000
A24: Share-based benefit plans | Q24: 1000000 | U24: 3000000 | Y24: 7000000 | Z24: 10000000 | AA24: 14000000 | AG24: 1000000 | AH24: 3000000 | AI24: 7000000
A25: Acquisition cost of treasury shares | Q25: -30000000 | U25: -28000000 | Y25: -35000000 | Z25: -35000000 | AA25: -62000000 | AG25: -30000000 | AH25: -28000000 | AI25: -35000000
A26: Share trading premiums | Q26: -40000000 | U26: -42000000 | Y26: -44000000 | Z26: -44000000 | AA26: -44000000 | AG26: -40000000 | AH26: -42000000 | AI26: -44000000
A27: Issuance premiums | Q27: 640000000 | U27: 640000000 | Y27: 640000000 | Z27: 640000000 | AA27: 640000000 | AG27: 640000000 | AH27: 640000000 | AI27: 640000000
A28: Legal reserve | Q28: 787000000 | U28: 787000000 | Y28: 787000000 | Z28: 787000000 | AA28: 787000000 | AG28: 787000000 | AH28: 787000000 | AI28: 787000000
A29: Reserve for investments | Q29: 5325000000 | U29: 4236000000 | Y29: 6587000000 | Z29: 6587000000 | AA29: 5802000000 | AG29: 5325000000 | AH29: 4236000000 | AI29: 6587000000
A30: Reserve for purchase of treasury shares | Q30: 35000000 | U30: 36000000 | Y30: 33000000 | Z30: 33000000 | AA30: 27000000 | AG30: 35000000 | AH30: 36000000 | AI30: 33000000
A31: Other comprehensive income | Q31: -684000000 | U31: -331000000 | Y31: -338000000 | Z31: -193000000 | AA31: -211000000 | AG31: -684000000 | AH31: -331000000 | AI31: -338000000
A32: Unappropriated retained earnings and losses | Q32: -1244000000 | U32: 2418000000 | Y32: -756000000 | Z32: -352000000 | AA32: 1640000000 | AG32: -1244000000 | AH32: 2418000000 | AI32: -756000000
A33: Shareholders' equity attributable to shareholders of the parent company | B33: 9.2013416e+09 | C33: 7.9936736e+09 | D33: 7.5202407e+09 | E33: 8057000000 | F33: 8.0462431e+09 | G33: 7.6210066e+09 | H33: 7.8772457e+09 | I33: 8184000000 | J33: 8.4795123e+09 | K33: 9.2989443e+09 | L33: 1.002867e+10 | M33: 10454000000 | N33: 1.0822931e+10 | O33: 1.1151228e+10 | P33: 1.0963978e+10 | Q33: 8949000000 | R33: 9813000000 | S33: 10418000000 | T33: 11926000000 | U33: 11652000000 | V33: 11675000000 | W33: 11694000000 | X33: 11412000000 | Y33: 10814000000 | Z33: 11366000000 | AA33: 12526000000 | AC33: 9.0597571e+09 | AD33: 8057000000 | AE33: 8184000000 | AF33: 10454000000 | AG33: 8949000000 | AH33: 11652000000 | AI33: 10814000000
A34: Non-controlling interest | B34: 95083935 | C34: 85406472 | D34: 87172627 | E34: 74000000 | F34: 73622457 | G34: 65871013 | H34: 75673412 | I34: 80000000 | J34: 84183299 | K34: 95901715 | L34: 1.0068961e+08 | M34: 98000000 | N34: 1.0067399e+08 | O34: 1.4681205e+08 | P34: 1.3620768e+08 | Q34: 102000000 | R34: 154000000 | S34: 187000000 | T34: 209000000 | U34: 218000000 | V34: 233000000 | W34: 230000000 | X34: 222000000 | Y34: 230000000 | Z34: 269000000 | AA34: 269000000 | AC34: 92676702 | AD34: 74000000 | AE34: 80000000 | AF34: 98000000 | AG34: 102000000 | AH34: 218000000 | AI34: 230000000
A35: TOTAL SHAREHOLDERS' EQUITY | B35: 9.2964256e+09 | C35: 8.0790801e+09 | D35: 7.6074133e+09 | E35: 8131000000 | F35: 8.1198656e+09 | G35: 7.6868777e+09 | H35: 7.9529191e+09 | I35: 8264000000 | J35: 8.5636956e+09 | K35: 9.394846e+09 | L35: 1.0129359e+10 | M35: 10552000000 | N35: 1.0923605e+10 | O35: 1.129804e+10 | P35: 1.1100186e+10 | Q35: 9051000000 | R35: 9967000000 | S35: 10605000000 | T35: 12135000000 | U35: 11870000000 | V35: 11908000000 | W35: 11924000000 | X35: 11634000000 | Y35: 11044000000 | Z35: 11635000000 | AA35: 12795000000 | AC35: 9.1524338e+09 | AD35: 8131000000 | AE35: 8264000000 | AF35: 10552000000 | AG35: 9051000000 | AH35: 11870000000 | AI35: 11044000000
A36: Provisions (no corriente) | E36: 2219000000 | I36: 2519000000 | J36: 2.4990295e+09 | K36: 2.5365077e+09 | L36: 2.5511388e+09 | M36: 2571000000 | N36: 2.165174e+09 | O36: 2.1596919e+09 | P36: 2.1788658e+09 | Q36: 2660000000 | R36: 686000000 | S36: 771000000 | T36: 756000000 | U36: 1084000000 | V36: 1079000000 | W36: 1093000000 | X36: 1123000000 | Y36: 610000000 | Z36: 639000000 | AA36: 661000000 | AC36: 2.4174092e+09 | AD36: 2219000000 | AE36: 2519000000 | AF36: 2571000000 | AG36: 2660000000 | AH36: 1084000000 | AI36: 610000000
A37: Contract liabilities (no corriente) | Q37: 34000000 | R37: 33000000 | S37: 32000000 | T37: 31000000 | U37: 114000000 | V37: 149000000 | W37: 167000000 | X37: 166000000 | Y37: 180000000 | Z37: 212000000 | AA37: 236000000 | AC37: 4909360.4 | AG37: 34000000 | AH37: 114000000 | AI37: 180000000
A38: Deferred income tax liabilities, net (no corriente) | E38: 1423000000 | I38: 1805000000 | J38: 1.6637553e+09 | K38: 1.3320739e+09 | L38: 7.9697588e+08 | M38: 1733000000 | N38: 1.5841733e+09 | O38: 1.3853053e+09 | P38: 1.0350304e+09 | Q38: 1242000000 | R38: 1066000000 | S38: 927000000 | T38: 92000000 | U38: 90000000 | V38: 95000000 | W38: 104000000 | X38: 389000000 | Y38: 373000000 | Z38: 511000000 | AA38: 446000000 | AC38: 1.6236123e+09 | AD38: 1423000000 | AE38: 1805000000 | AF38: 1733000000 | AG38: 1242000000 | AH38: 90000000 | AI38: 373000000
A39: Income tax liability (no corriente) | E39: 42000000 | I39: 29000000 | J39: 48632432 | K39: 40954696 | L39: 33035058 | M39: 26000000 | N39: 20703447 | O39: 15801100 | P39: 10793083 | Q39: 4000000 | R39: 4000000 | S39: 3000000 | T39: 3000000 | U39: 2000000 | V39: 2000000 | W39: 2000000 | X39: 1000000 | Y39: 830000000 | Z39: 865000000 | AA39: 801000000 | AC39: 56557836 | AD39: 42000000 | AE39: 29000000 | AF39: 26000000 | AG39: 4000000 | AH39: 2000000 | AI39: 830000000
A40: Taxes payable (no corriente) | E40: 3000000 | I40: 2000000 | J40: 1828896.6 | K40: 1613270 | L40: 1319226.3 | M40: 1000000 | N40: 848659.14 | O40: 636259.72 | P40: 462805.57 | Q40: 178222.63 | U40: 217269.99 | Y40: 18000000 | Z40: 19000000 | AA40: 12000000 | AC40: 23845465 | AD40: 3000000 | AE40: 2000000 | AF40: 1000000 | AG40: 178222.63 | AH40: 217269.99 | AI40: 18000000
A41: Salaries and social security (no corriente) | E41: 46000000 | I41: 32000000 | J41: 20712479 | K41: 13481187 | L41: 3780875.3 | M41: 1000000 | N41: 2095277.1 | O41: 11710.302 | P41: 1217007.2 | Q41: 457933.14 | S41: 4000000 | T41: 8000000 | U41: 34000000 | V41: 33000000 | W41: 34000000 | X41: 26000000 | Y41: 63000000 | Z41: 98000000 | AA41: 134000000 | AD41: 46000000 | AE41: 32000000 | AF41: 1000000 | AG41: 457933.14 | AH41: 34000000 | AI41: 63000000
...

Sheet Flujo de efectivo
A1: Estado de flujo de efectivo
A2: Consolidado, en dólares (la compañía reporta redondeado al millón)
A4: En dólares | B4: 2020Q1 | C4: 2020Q2 | D4: 2020Q3 | E4: 2020Q4 | F4: 2021Q1 | G4: 2021Q2 | H4: 2021Q3 | I4: 2021Q4 | J4: 2022Q1 | K4: 2022Q2 | L4: 2022Q3 | M4: 2022Q4 | N4: 2023Q1 | O4: 2023Q2 | P4: 2023Q3 | Q4: 2023Q4 | R4: 2024Q1 | S4: 2024Q2 | T4: 2024Q3 | U4: 2024Q4 | V4: 2025Q1 | W4: 2025Q2 | X4: 2025Q3 | Y4: 2025Q4 | Z4: 2026Q1 | AA4: 2026Q2 | AC4: FY19 | AD4: FY20 | AE4: FY21 | AF4: FY22 | AG4: FY23 | AH4: FY24 | AI4: FY25
A5: Net profit | B5: 1.0341061e+08 | I5: 2.4616607e+08 | J5: 2.4778465e+08 | K5: 7.9740766e+08 | L5: 6.7996659e+08 | M5: 4.7896486e+08 | N5: 341000000 | O5: 380000000 | P5: -137000000 | Q5: -1861000000 | R5: 657000000 | S5: 535000000 | T5: 1485000000 | U5: -284000000 | V5: -10000000 | W5: 58000000 | X5: -198000000 | Y5: -649000000 | Z5: 409000000 | AA5: 1205000000 | AE5: 16000000 | AF5: 2234000000 | AG5: -1277000000 | AH5: 2393000000 | AI5: -799000000
A6: Income from equity interests in associates and joint ventures | B6: -23121252 | C6: -34066627 | D6: -61857544 | E6: -62755283 | F6: -57794126 | G6: -15316626 | H6: -44839298 | I6: -1.5990343e+08 | J6: -1.1470487e+08 | K6: -1.3110266e+08 | L6: -1.4043093e+08 | M6: -70052977 | N6: -89000000 | O6: -94000000 | P6: -44000000 | Q6: 133000000 | R6: -129000000 | S6: -27000000 | T6: -107000000 | U6: -133000000 | V6: -81000000 | W6: 6000000 | X6: -32000000 | Y6: -15000000 | Z6: -101000000 | AA6: -115000000 | AC6: -1.655304e+08 | AD6: -188000000 | AE6: -287000000 | AF6: -446000000 | AG6: -94000000 | AH6: -396000000 | AI6: -122000000
A7: Depreciation of property, plant and equipment | B7: 7.1050631e+08 | C7: 6.3594987e+08 | D7: 6.4690974e+08 | E7: 4.6885197e+08 | F7: 6.876891e+08 | G7: 7.7223897e+08 | H7: 7.1557676e+08 | I7: 6.4414285e+08 | J7: 5.8913223e+08 | K7: 6.3207334e+08 | L7: 6.6069219e+08 | M7: 6.8559954e+08 | N7: 709000000 | O7: 791000000 | P7: 798000000 | Q7: 718000000 | R7: 576000000 | S7: 561000000 | T7: 595000000 | U7: 714000000 | V7: 718000000 | W7: 704000000 | X7: 750000000 | Y7: 685000000 | Z7: 653000000 | AA7: 788000000 | AC7: 3.03086e+09 | AD7: 2460000000 | AE7: 2816000000 | AF7: 2551000000 | AG7: 3016000000 | AH7: 2446000000 | AI7: 2857000000
A8: Amortization of intangible assets | B8: 10893041 | C8: 10960567 | D8: 13655087 | E8: 12738572 | F8: 11771204 | G8: 12740793 | H8: 12820047 | I8: 13418191 | J8: 11086855 | K8: 12648249 | L8: 11957062 | M8: 12078738 | N8: 10000000 | O8: 9000000 | P8: 11000000 | Q8: 7000000 | R8: 10000000 | S8: 10000000 | T8: 11000000 | U8: 12000000 | V8: 14000000 | W8: 17000000 | X8: 13000000 | Y8: 17000000 | Z8: 17000000 | AA8: 14000000 | AC8: 49318420 | AD8: 48000000 | AE8: 51000000 | AF8: 43000000 | AG8: 37000000 | AH8: 43000000 | AI8: 61000000
A9: Depreciation of right-of-use assets | B9: 77374782 | C9: 58165063 | D9: 64219874 | E9: 56142226 | F9: 47604466 | G9: 50750295 | H9: 52391397 | I9: 51024961 | J9: 50566190 | K9: 49965669 | L9: 56244660 | M9: 57955723 | N9: 56000000 | O9: 54000000 | P9: 55000000 | Q9: 55000000 | R9: 66000000 | S9: 67000000 | T9: 68000000 | U9: 69000000 | V9: 74000000 | W9: 67000000 | X9: 73000000 | Y9: 72000000 | Z9: 73000000 | AA9: 76000000 | AC9: 2.1831814e+08 | AD9: 254000000 | AE9: 201000000 | AF9: 214000000 | AG9: 220000000 | AH9: 270000000 | AI9: 286000000
A10: Retirement of property, plant and equipment and intangible assets and consumption of materials | B10: 77130544 | C10: 38850766 | D10: 1.3739748e+08 | E10: 86157253 | F10: 83245683 | G10: 87131274 | H10: 73576370 | I10: 95191515 | J10: 85383793 | K10: 99507469 | L10: 1.1119108e+08 | M10: 75200482 | N10: 84000000 | O10: 79000000 | P10: 108000000 | Q10: 112000000 | R10: 90000000 | S10: 153000000 | T10: 145000000 | U10: 232000000 | V10: 99000000 | W10: 100000000 | X10: 138000000 | Y10: 343000000 | Z10: 56000000 | AA10: 92000000 | AC10: 3.9728958e+08 | AD10: 339000000 | AE10: 342000000 | AF10: 375000000 | AG10: 383000000 | AH10: 620000000 | AI10: 680000000
A11: Charge on income tax | B11: -12277059 | C11: -13093434 | D11: 1.2184434e+08 | E11: 91307687 | F11: 1.1213145e+08 | G11: 7.0218057e+08 | H11: 1.5505466e+08 | I11: -2.643523e+08 | J11: 2.0322149e+08 | K11: 1.8269598e+08 | L11: 2.8772186e+08 | M11: 1.6472634e+08 | N11: 85000000 | O11: 75000000 | P11: 0 | Q11: 860000000 | R11: -121000000 | S11: -79000000 | T11: -787000000 | U11: -216000000 | V11: 38000000 | W11: 61000000 | X11: 579000000 | Y11: 1042000000 | Z11: 243000000 | AA11: 593000000 | AC11: 5.4780009e+08 | AD11: 184000000 | AE11: 699000000 | AF11: 822000000 | AG11: -381000000 | AH11: -1373000000 | AI11: 1709000000
A12: Net increase in provisions | B12: 62883293 | C12: 1.8222683e+08 | D12: 1.0280915e+08 | E12: 56067220 | F12: 64651248 | G12: 79350556 | H12: 49387020 | I12: 3.1653194e+08 | J12: 71783167 | K12: 1.0537382e+08 | L12: 82356935 | M12: -1.3400178e+08 | N12: 99000000 | O12: 98000000 | P12: 111000000 | Q12: 118000000 | R12: 163000000 | S12: 199000000 | T12: 160000000 | U12: 226000000 | V12: 261000000 | W12: 247000000 | X12: 88000000 | Y12: 221000000 | Z12: 102000000 | AA12: 75000000 | AC12: 2.7193686e+08 | AD12: 396000000 | AE12: 510000000 | AF12: 139000000 | AG12: 426000000 | AH12: 748000000 | AI12: 817000000
A13: Inventories write-down and reversal of impairment losses of property, plant and equipment | M13: 26657164 | Q13: 1782000000 | T13: 21000000 | U13: 61000000 | X13: 5000000 | Y13: 0 | AF13: 123000000 | AG13: 2288000000 | AH13: 87000000 | AI13: -4000000
A14: Effect of changes in exchange rates, interest and others | J14: 7175502.8 | K14: 1.1896305e+08 | L14: -1.4617711e+08 | M14: -1.1053557e+08 | N14: 29000000 | O14: -34000000 | P14: -130000000 | Q14: -557000000 | R14: 242000000 | S14: 71000000 | T14: 100000000 | U14: 30000000 | V14: 243000000 | W14: 299000000 | X14: 173000000 | Y14: 237000000 | Z14: 291000000 | AA14: 45000000 | AE14: 440000000 | AF14: -73000000 | AG14: 709000000 | AH14: 613000000 | AI14: 963000000
A15: Share-based benefit plans | B15: 2393538.1 | C15: 2266171.3 | D15: 928545.91 | E15: 2162682.1 | F15: 1344312.2 | G15: 1298560.4 | H15: 524737.08 | I15: 497707.39 | J15: 497126.34 | K15: 483210.58 | L15: 3422625.9 | M15: 2925560.5 | N15: 4000000 | O15: 8000000 | P15: 3000000 | Q15: -12000000 | R15: 1000000 | S15: 1000000 | T15: 3000000 | U15: 2000000 | V15: 2000000 | W15: 3000000 | X15: 4000000 | Y15: 6000000 | Z15: 3000000 | AA15: 4000000 | AC15: 10241778 | AD15: 7000000 | AE15: 6000000 | AF15: 8000000 | AG15: 3000000 | AH15: 7000000 | AI15: 15000000
A16: Result from sale of assets | I16: 0 | V16: -14000000 | W16: -168000000 | X16: -34000000 | Y16: -3000000 | Z16: -4000000 | AA16: 0 | AE16: -57000000 | AH16: -6000000 | AI16: -219000000
A17: Result from changes in fair value of assets held for sale | V17: 200000000 | W17: 44000000 | X17: -4000000 | Y17: 178000000 | Z17: -14000000 | AA17: 147000000 | AH17: 260000000 | AI17: 418000000
A18: Result from revaluation of companies | X18: 0 | Y18: 0 | AI18: -45000000
A19: Other insurance income | AC19: -10345650 | AD19: -52000000 | AE19: -15000000 | AH19: -5000000
A20: Trade receivables | B20: 2.5058878e+08 | C20: 1.7520614e+08 | D20: -1.1892215e+08 | E20: 2.0705493e+08 | F20: 20514881 | G20: -1.6234134e+08 | H20: -1.2260328e+08 | I20: 3.5340211e+08 | J20: -1.1324163e+08 | K20: -2.3057622e+08 | L20: -1.8159833e+08 | M20: 71225670 | N20: 144000000 | O20: -175000000 | P20: -233000000 | Q20: 86000000 | R20: -448000000 | S20: -352000000 | T20: -287000000 | U20: 279000000 | V20: -14000000 | W20: -271000000 | X20: -250000000 | Y20: 176000000 | Z20: -58000000 | AA20: -330000000 | AC20: -2.4582345e+08 | AD20: 414000000 | AE20: 117000000 | AF20: -397000000 | AG20: -178000000 | AH20: -808000000 | AI20: -359000000
A21: Other receivables | B21: -65048875 | C21: 1.6680798e+08 | D21: 25671563 | E21: -45816357 | F21: -93344970 | G21: 55369764 | H21: -29333832 | I21: -1.5935595e+08 | J21: 1.5614457e+08 | K21: -1.3480727e+08 | L21: -68931980 | M21: 944326.48 | N21: 41000000 | O21: -177000000 | P21: 143000000 | Q21: -185000000 | R21: -128000000 | S21: -155000000 | T21: -85000000 | U21: -172000000 | V21: -224000000 | W21: -20000000 | X21: -25000000 | Y21: -161000000 | Z21: 1000000 | AA21: 115000000 | AC21: -2.7164602e+08 | AD21: 89000000 | AE21: -241000000 | AF21: -94000000 | AG21: -178000000 | AH21: -540000000 | AI21: -430000000
A22: Inventories | B22: -1.7832673e+08 | C22: 82396802 | D22: 60901688 | E22: 1.7827751e+08 | F22: -25383777 | G22: -86237183 | H22: -94679032 | I22: -79722769 | J22: -2673226.5 | K22: -2.0945907e+08 | L22: -2.7125785e+08 | M22: 2.5775175e+08 | N22: -126000000 | O22: -25000000 | P22: 127000000 | Q22: 68000000 | R22: 125000000 | S22: 1000000 | T22: -156000000 | U22: 157000000 | V22: -69000000 | W22: 132000000 | X22: -54000000 | Y22: 85000000 | Z22: -5000000 | AA22: -200000000 | AC22: 1.397286e+08 | AD22: 162000000 | AE22: -303000000 | AF22: -232000000 | AG22: 44000000 | AH22: 127000000 | AI22: 94000000
A23: Accounts payable | B23: -55458440 | C23: -1.7738345e+08 | D23: -1.3615487e+08 | E23: 53929540 | F23: 1.9068899e+08 | G23: -63299498 | H23: -52823533 | I23: -56250889 | J23: -18215459 | K23: 79729745 | L23: 3.1215233e+08 | M23: 2.204848e+08 | N23: 27000000 | O23: 118000000 | P23: 330000000 | Q23: 261000000 | R23: 41000000 | S23: 196000000 | T23: 477000000 | U23: -12000000 | V23: -282000000 | W23: 196000000 | X23: -70000000 | Y23: -124000000 | Z23: 81000000 | AA23: -406000000 | AC23: 6.1149439e+08 | AD23: -490000000 | AE23: -91000000 | AF23: 600000000 | AG23: 736000000 | AH23: 702000000 | AI23: -280000000
A24: Taxes payable | B24: 5943138.8 | C24: 177738.92 | D24: 22735720 | E24: -14751242 | F24: 91130809 | G24: -56827983 | H24: -14949862 | I24: -48914682 | J24: 1.776148e+08 | K24: -58375228 | L24: 27108082 | M24: -56091758 | N24: -7000000 | O24: 61000000 | P24: -6000000 | Q24: 26000000 | R24: 107000000 | S24: 37000000 | T24: -14000000 | U24: 11000000 | V24: -12000000 | W24: 65000000 | X24: -23000000 | Y24: -15000000 | Z24: 123000000 | AA24: 59000000 | AC24: -23786685 | AD24: 27000000 | AE24: -33000000 | AF24: 112000000 | AG24: 74000000 | AH24: 141000000 | AI24: 15000000
A25: Salaries and social security | B25: -28901565 | C25: 13804390 | D25: 83473546 | E25: 41766016 | F25: -27665718 | G25: 13262346 | H25: 15505466 | I25: 16265077 | J25: -33335604 | K25: 16963234 | L25: 32138752 | M25: 71250359 | N25: -58000000 | O25: 21000000 | P25: 85000000 | Q25: 183000000 | R25: -48000000 | S25: 98000000 | T25: 130000000 | U25: 99000000 | V25: 27000000 | W25: -111000000 | X25: 27000000 | Y25: 54000000 | Z25: 64000000 | AA25: -24000000 | AC25: 94191119 | AD25: 90000000 | AE25: 10000000 | AF25: 80000000 | AG25: 231000000 | AH25: 279000000 | AI25: -3000000
A26: Other liabilities | B26: 2816885 | C26: -325854.69 | D26: 832960.3 | E26: 1.0970924e+08 | F26: -26852353 | G26: -16955793 | H26: -24374552 | I26: -18206136 | J26: -18984598 | K26: -4170870.2 | L26: -2397313.4 | M26: 14387092 | N26: -9000000 | O26: 35000000 | P26: 28000000 | Q26: 12000000 | R26: -49000000 | S26: 1000000 | T26: -1000000 | U26: 268000000 | V26: -104000000 | W26: -288000000 | X26: 87000000 | Y26: -87000000 | Z26: -80000000 | AA26: 56000000 | AC26: 16681841 | AD26: 109000000 | AE26: -92000000 | AF26: -14000000 | AG26: 66000000 | AH26: 219000000 | AI26: -392000000
A27: Decrease in provisions due to payment/use | M27: -57171870 | N27: -48000000 | O27: -57000000 | P27: -333000000 | Q27: -53000000 | R27: -36000000 | S27: -36000000 | T27: -47000000 | U27: -52000000 | V27: -59000000 | W27: -41000000 | X27: -34000000 | Y27: -32000000 | Z27: -26000000 | AA27: -32000000 | AE27: -81000000 | AF27: -159000000 | AG27: -491000000 | AH27: -171000000 | AI27: -166000000
A28: Contract assets | B28: -8418089.7 | C28: 3762140.5 | D28: 95585.608 | E28: -6225524.1 | F28: 5422435.6 | G28: -10941968 | H28: 2911776.4 | I28: -3971704.9 | J28: -3901972.8 | K28: -3738523.9 | L28: 14140461 | M28: 1623254 | N28: -9000000 | O28: 1000000 | P28: -3000000 | Q28: -1000000 | R28: -8000000 | S28: -5000000 | T28: -17000000 | U28: 7000000 | V28: 5000000 | W28: 0 | X28: 10000000 | Y28: 3000000 | Z28: -2000000 | AA28: -2000000 | AC28: 9244606.9 | AD28: -8000000 | AE28: -6000000 | AF28: 7000000 | AG28: -12000000 | AH28: -23000000 | AI28: 18000000
A29: Contract liabilities | B29: 1400301.2 | C29: -19329108 | D29: 42890628 | E29: -17451469 | F29: -6902308.7 | G29: 14124505 | H29: 1.0390823e+08 | I29: -39328838 | J29: 1.6772855e+08 | K29: -18913031 | L29: 61098298 | M29: -1.7007752e+08 | N29: 17000000 | O29: 75000000 | P29: -16000000 | Q29: -51000000 | R29: -16000000 | S29: 15000000 | T29: 9000000 | U29: 80000000 | V29: 45000000 | W29: 35000000 | X29: -9000000 | Y29: 13000000 | Z29: 63000000 | AA29: 71000000 | AC29: 16120933 | AD29: -22000000 | AE29: 56000000 | AF29: -29000000 | AG29: 25000000 | AH29: 88000000 | AI29: 84000000
A30: Dividends received | B30: 2116734.4 | C30: 29119560 | D30: 5434724.6 | E30: 1525128.4 | F30: 316308.74 | G30: 40085069 | H30: 0 | I30: 12731355 | L30: 1888345.3 | M30: 26916391 | N30: 198000000 | O30: 73000000 | P30: 0 | Q30: 5000000 | T30: 1000000 | U30: 37000000 | X30: 21000000 | Y30: 38000000 | AC30: 16848036 | AD30: 38000000 | AE30: 56000000 | AF30: 94000000 | AG30: 276000000 | AH30: 174000000 | AI30: 224000000
